<?xml version="1.0"?>
<robot name="hiyoko" xmlns:xacro="http://ros.org/wiki/xacro">
  <xacro:include filename="$(find kobuki_description)/urdf/kobuki.urdf.xacro"/>
  <xacro:include filename="$(find realsense2_description)/urdf/_d435.urdf.xacro"/>

  <xacro:kobuki/>

  <material name="orange">
    <color rgba="1.0 0.5 0.2 1" />
  </material>
  <material name="gray">
    <color rgba="0.25 0.25 0.25 1" />
  </material>

  <!-- spine -->
  <joint name="spine_joint" type="fixed">
    <parent link="base_link"/>
    <child  link="spine_link"/>
    <origin xyz="0.05 0 0.09" rpy="0 0 0"/>
  </joint>
  <link name="spine_link">
    <visual>
      <origin xyz="0 0 0.3735" rpy="0 0 0"/>
      <geometry>
        <!-- <cylinder length="0.75" radius="0.015" /> -->
        <box size="0.03 0.03 0.75"/>
      </geometry>
      <material name="gray" />
    </visual>
  </link>

  <!-- neck -->
  <joint name="neck_joint" type="revolute">
  <!-- <joint name="neck_joint" type="fixed"> -->
    <parent link="spine_link" />
    <child  link="neck_link" />
    <origin xyz="0 0 0.75" rpy="0 0 0" />
    <axis xyz="0 1 0" />
    <limit lower="-1.5" upper="1.5" effort="1000" velocity="0.5" />
  </joint>
  <link name="neck_link">
    <visual>
      <origin xyz="0 0 0" rpy="0 0 0"/>
      <geometry>
        <!-- <cylinder length="0.02" radius="0.02" /> -->
        <box size="0.05 0.045 0.09 " />
      </geometry>
      <material name="gray" />
    </visual>
  </link>

  <!--  lidar  -->
  <joint name="base_laser_link_joint" type="fixed">
    <parent link="base_footprint" />
    <child link="base_laser_link" />
    <origin xyz="0.14 0.0 0.13" rpy="0 0 0"/>
  </joint>
  <link name="base_laser_link">
    <visual>
      <origin xyz="0 0 0" rpy="0 3.14 3.14"/>
      <geometry>
        <!-- <mesh filename="package://happymimi_description/meshes/stl/lrf.stl" /> -->
        <cylinder length="0.08" radius="0.03" />
      </geometry>
      <material name="orange" />
    </visual>
  </link>

  <!--  realsense  -->
  <xacro:sensor_d435 parent="neck_link">
  <!-- <xacro:sensor_d435 parent="base_link"> -->
    <origin xyz="0.10 0 0.11"/>
    <!-- <origin xyz="0.12 0 1.02"/> -->
  </xacro:sensor_d435>

  <!--  respeaker  -->
  <joint name="respeaker_link_joint" type="fixed">
    <parent link="neck_link" />
    <child link="respeaker_link" />
    <origin xyz="0.015 0 0.17" rpy="0 0 0"/>
  </joint>
  <link name="respeaker_link">
    <visual>
      <origin xyz="0 0 0" rpy="0 0 0"/>
      <geometry>
        <cylinder length="0.0015" radius="0.035" />
      </geometry>
      <material name="orange" />
    </visual>
  </link>

</robot>
